2023-10-05 17:08:38,447 ERROR frappe Failed to run after request hook
Site: site123.local
Form Dict: {}
Traceback (most recent call last):
  File "/home/nirosh/frappe-bench/apps/frappe/frappe/app.py", line 84, in application
    init_request(request)
  File "/home/nirosh/frappe-bench/apps/frappe/frappe/app.py", line 172, in init_request
    frappe.local.http_request = frappe.auth.HTTPRequest()
  File "/home/nirosh/frappe-bench/apps/frappe/frappe/auth.py", line 34, in __init__
    self.set_session()
  File "/home/nirosh/frappe-bench/apps/frappe/frappe/auth.py", line 70, in set_session
    frappe.local.login_manager = LoginManager()
  File "/home/nirosh/frappe-bench/apps/frappe/frappe/auth.py", line 119, in __init__
    self.make_session(resume=True)
  File "/home/nirosh/frappe-bench/apps/frappe/frappe/auth.py", line 207, in make_session
    frappe.local.session_obj = Session(
  File "/home/nirosh/frappe-bench/apps/frappe/frappe/sessions.py", line 230, in __init__
    self.resume()
  File "/home/nirosh/frappe-bench/apps/frappe/frappe/sessions.py", line 303, in resume
    data = self.get_session_record()
  File "/home/nirosh/frappe-bench/apps/frappe/frappe/sessions.py", line 321, in get_session_record
    r = self.get_session_data()
  File "/home/nirosh/frappe-bench/apps/frappe/frappe/sessions.py", line 337, in get_session_data
    data = self.get_session_data_from_db()
  File "/home/nirosh/frappe-bench/apps/frappe/frappe/sessions.py", line 362, in get_session_data_from_db
    frappe.db.get_value(
  File "/home/nirosh/frappe-bench/apps/frappe/frappe/database/database.py", line 509, in get_value
    result = self.get_values(
  File "/home/nirosh/frappe-bench/apps/frappe/frappe/database/database.py", line 606, in get_values
    out = self._get_values_from_table(
  File "/home/nirosh/frappe-bench/apps/frappe/frappe/database/database.py", line 835, in _get_values_from_table
    return query.run(as_dict=as_dict, debug=debug, update=update, run=run, pluck=pluck)
  File "/home/nirosh/frappe-bench/apps/frappe/frappe/query_builder/utils.py", line 87, in execute_query
    result = frappe.db.sql(query, params, *args, **kwargs)  # nosemgrep
  File "/home/nirosh/frappe-bench/apps/frappe/frappe/database/database.py", line 201, in sql
    self.connect()
  File "/home/nirosh/frappe-bench/apps/frappe/frappe/database/database.py", line 115, in connect
    self._conn = self.get_connection()
  File "/home/nirosh/frappe-bench/apps/frappe/frappe/database/mariadb/database.py", line 98, in get_connection
    conn = self._get_connection()
  File "/home/nirosh/frappe-bench/apps/frappe/frappe/database/mariadb/database.py", line 104, in _get_connection
    return self.create_connection()
  File "/home/nirosh/frappe-bench/apps/frappe/frappe/database/mariadb/database.py", line 107, in create_connection
    return pymysql.connect(**self.get_connection_settings())
  File "/home/nirosh/frappe-bench/env/lib/python3.10/site-packages/pymysql/connections.py", line 352, in __init__
    self.connect()
  File "/home/nirosh/frappe-bench/env/lib/python3.10/site-packages/pymysql/connections.py", line 636, in connect
    self._request_authentication()
  File "/home/nirosh/frappe-bench/env/lib/python3.10/site-packages/pymysql/connections.py", line 911, in _request_authentication
    auth_packet = self._read_packet()
  File "/home/nirosh/frappe-bench/env/lib/python3.10/site-packages/pymysql/connections.py", line 729, in _read_packet
    packet.raise_for_error()
  File "/home/nirosh/frappe-bench/env/lib/python3.10/site-packages/pymysql/protocol.py", line 221, in raise_for_error
    err.raise_mysql_exception(self._data)
  File "/home/nirosh/frappe-bench/env/lib/python3.10/site-packages/pymysql/err.py", line 143, in raise_mysql_exception
    raise errorclass(errno, errval)
pymysql.err.OperationalError: (1698, "Access denied for user '_e62c1393ab75f65c'@'localhost'")

During handling of the above exception, another exception occurred:

Traceback (most recent call last):
  File "/home/nirosh/frappe-bench/apps/frappe/frappe/utils/caching.py", line 55, in wrapper
    return frappe.local.request_cache[func][args_key]
KeyError: 5740354900026072187

During handling of the above exception, another exception occurred:

Traceback (most recent call last):
  File "/home/nirosh/frappe-bench/apps/frappe/frappe/utils/caching.py", line 55, in wrapper
    return frappe.local.request_cache[func][args_key]
KeyError: -8626848910413166604

During handling of the above exception, another exception occurred:

Traceback (most recent call last):
  File "/home/nirosh/frappe-bench/apps/frappe/frappe/website/serve.py", line 17, in get_response
    endpoint, renderer_instance = path_resolver.resolve()
  File "/home/nirosh/frappe-bench/apps/frappe/frappe/website/path_resolver.py", line 36, in resolve
    resolve_redirect(self.path, request.query_string)
  File "/home/nirosh/frappe-bench/apps/frappe/frappe/website/path_resolver.py", line 107, in resolve_redirect
    redirects = frappe.get_hooks("website_redirects")
  File "/home/nirosh/frappe-bench/apps/frappe/frappe/__init__.py", line 1513, in get_hooks
    hooks = _dict(cache().get_value("app_hooks", _load_app_hooks))
  File "/home/nirosh/frappe-bench/apps/frappe/frappe/utils/redis_wrapper.py", line 81, in get_value
    val = generator()
  File "/home/nirosh/frappe-bench/apps/frappe/frappe/utils/caching.py", line 57, in wrapper
    return_val = func(*args, **kwargs)
  File "/home/nirosh/frappe-bench/apps/frappe/frappe/__init__.py", line 1476, in _load_app_hooks
    apps = [app_name] if app_name else get_installed_apps(_ensure_on_bench=True)
  File "/home/nirosh/frappe-bench/apps/frappe/frappe/utils/caching.py", line 57, in wrapper
    return_val = func(*args, **kwargs)
  File "/home/nirosh/frappe-bench/apps/frappe/frappe/__init__.py", line 1432, in get_installed_apps
    installed = json.loads(db.get_global("installed_apps") or "[]")
  File "/home/nirosh/frappe-bench/apps/frappe/frappe/database/database.py", line 975, in get_global
    return self.get_default(key, user)
  File "/home/nirosh/frappe-bench/apps/frappe/frappe/database/database.py", line 979, in get_default
    d = self.get_defaults(key, parent)
  File "/home/nirosh/frappe-bench/apps/frappe/frappe/database/database.py", line 995, in get_defaults
    defaults = frappe.defaults.get_defaults_for(parent)
  File "/home/nirosh/frappe-bench/apps/frappe/frappe/defaults.py", line 238, in get_defaults_for
    frappe.qb.from_(table)
  File "/home/nirosh/frappe-bench/apps/frappe/frappe/query_builder/utils.py", line 87, in execute_query
    result = frappe.db.sql(query, params, *args, **kwargs)  # nosemgrep
  File "/home/nirosh/frappe-bench/apps/frappe/frappe/database/database.py", line 201, in sql
    self.connect()
  File "/home/nirosh/frappe-bench/apps/frappe/frappe/database/database.py", line 115, in connect
    self._conn = self.get_connection()
  File "/home/nirosh/frappe-bench/apps/frappe/frappe/database/mariadb/database.py", line 98, in get_connection
    conn = self._get_connection()
  File "/home/nirosh/frappe-bench/apps/frappe/frappe/database/mariadb/database.py", line 104, in _get_connection
    return self.create_connection()
  File "/home/nirosh/frappe-bench/apps/frappe/frappe/database/mariadb/database.py", line 107, in create_connection
    return pymysql.connect(**self.get_connection_settings())
  File "/home/nirosh/frappe-bench/env/lib/python3.10/site-packages/pymysql/connections.py", line 352, in __init__
    self.connect()
  File "/home/nirosh/frappe-bench/env/lib/python3.10/site-packages/pymysql/connections.py", line 636, in connect
    self._request_authentication()
  File "/home/nirosh/frappe-bench/env/lib/python3.10/site-packages/pymysql/connections.py", line 911, in _request_authentication
    auth_packet = self._read_packet()
  File "/home/nirosh/frappe-bench/env/lib/python3.10/site-packages/pymysql/connections.py", line 729, in _read_packet
    packet.raise_for_error()
  File "/home/nirosh/frappe-bench/env/lib/python3.10/site-packages/pymysql/protocol.py", line 221, in raise_for_error
    err.raise_mysql_exception(self._data)
  File "/home/nirosh/frappe-bench/env/lib/python3.10/site-packages/pymysql/err.py", line 143, in raise_mysql_exception
    raise errorclass(errno, errval)
pymysql.err.OperationalError: (1698, "Access denied for user '_e62c1393ab75f65c'@'localhost'")

During handling of the above exception, another exception occurred:

Traceback (most recent call last):
  File "/home/nirosh/frappe-bench/apps/frappe/frappe/utils/caching.py", line 55, in wrapper
    return frappe.local.request_cache[func][args_key]
KeyError: -4926410494428837262

During handling of the above exception, another exception occurred:

Traceback (most recent call last):
  File "/home/nirosh/frappe-bench/apps/frappe/frappe/app.py", line 113, in application
    response = handle_exception(e)
  File "/home/nirosh/frappe-bench/apps/frappe/frappe/app.py", line 367, in handle_exception
    response = get_response("message", http_status_code=http_status_code)
  File "/home/nirosh/frappe-bench/apps/frappe/frappe/website/serve.py", line 26, in get_response
    response = ErrorPage(exception=e).render()
  File "/home/nirosh/frappe-bench/apps/frappe/frappe/website/page_renderers/error_page.py", line 7, in __init__
    super().__init__(path=path, http_status_code=http_status_code)
  File "/home/nirosh/frappe-bench/apps/frappe/frappe/website/page_renderers/template_page.py", line 45, in __init__
    self.set_template_path()
  File "/home/nirosh/frappe-bench/apps/frappe/frappe/website/page_renderers/template_page.py", line 53, in set_template_path
    for app in frappe.get_installed_apps(frappe_last=True):
  File "/home/nirosh/frappe-bench/apps/frappe/frappe/utils/caching.py", line 57, in wrapper
    return_val = func(*args, **kwargs)
  File "/home/nirosh/frappe-bench/apps/frappe/frappe/__init__.py", line 1432, in get_installed_apps
    installed = json.loads(db.get_global("installed_apps") or "[]")
  File "/home/nirosh/frappe-bench/apps/frappe/frappe/database/database.py", line 975, in get_global
    return self.get_default(key, user)
  File "/home/nirosh/frappe-bench/apps/frappe/frappe/database/database.py", line 979, in get_default
    d = self.get_defaults(key, parent)
  File "/home/nirosh/frappe-bench/apps/frappe/frappe/database/database.py", line 995, in get_defaults
    defaults = frappe.defaults.get_defaults_for(parent)
  File "/home/nirosh/frappe-bench/apps/frappe/frappe/defaults.py", line 238, in get_defaults_for
    frappe.qb.from_(table)
  File "/home/nirosh/frappe-bench/apps/frappe/frappe/query_builder/utils.py", line 87, in execute_query
    result = frappe.db.sql(query, params, *args, **kwargs)  # nosemgrep
  File "/home/nirosh/frappe-bench/apps/frappe/frappe/database/database.py", line 201, in sql
    self.connect()
  File "/home/nirosh/frappe-bench/apps/frappe/frappe/database/database.py", line 115, in connect
    self._conn = self.get_connection()
  File "/home/nirosh/frappe-bench/apps/frappe/frappe/database/mariadb/database.py", line 98, in get_connection
    conn = self._get_connection()
  File "/home/nirosh/frappe-bench/apps/frappe/frappe/database/mariadb/database.py", line 104, in _get_connection
    return self.create_connection()
  File "/home/nirosh/frappe-bench/apps/frappe/frappe/database/mariadb/database.py", line 107, in create_connection
    return pymysql.connect(**self.get_connection_settings())
  File "/home/nirosh/frappe-bench/env/lib/python3.10/site-packages/pymysql/connections.py", line 352, in __init__
    self.connect()
  File "/home/nirosh/frappe-bench/env/lib/python3.10/site-packages/pymysql/connections.py", line 636, in connect
    self._request_authentication()
  File "/home/nirosh/frappe-bench/env/lib/python3.10/site-packages/pymysql/connections.py", line 911, in _request_authentication
    auth_packet = self._read_packet()
  File "/home/nirosh/frappe-bench/env/lib/python3.10/site-packages/pymysql/connections.py", line 729, in _read_packet
    packet.raise_for_error()
  File "/home/nirosh/frappe-bench/env/lib/python3.10/site-packages/pymysql/protocol.py", line 221, in raise_for_error
    err.raise_mysql_exception(self._data)
  File "/home/nirosh/frappe-bench/env/lib/python3.10/site-packages/pymysql/err.py", line 143, in raise_mysql_exception
    raise errorclass(errno, errval)
pymysql.err.OperationalError: (1698, "Access denied for user '_e62c1393ab75f65c'@'localhost'")

During handling of the above exception, another exception occurred:

Traceback (most recent call last):
  File "/home/nirosh/frappe-bench/apps/frappe/frappe/utils/caching.py", line 55, in wrapper
    return frappe.local.request_cache[func][args_key]
KeyError: 5740354900026072187

During handling of the above exception, another exception occurred:

Traceback (most recent call last):
  File "/home/nirosh/frappe-bench/apps/frappe/frappe/utils/caching.py", line 55, in wrapper
    return frappe.local.request_cache[func][args_key]
KeyError: -8626848910413166604

During handling of the above exception, another exception occurred:

Traceback (most recent call last):
  File "/home/nirosh/frappe-bench/apps/frappe/frappe/app.py", line 127, in application
    run_after_request_hooks(request, response)
  File "/home/nirosh/frappe-bench/apps/frappe/frappe/app.py", line 143, in run_after_request_hooks
    for after_request_task in frappe.get_hooks("after_request"):
  File "/home/nirosh/frappe-bench/apps/frappe/frappe/__init__.py", line 1513, in get_hooks
    hooks = _dict(cache().get_value("app_hooks", _load_app_hooks))
  File "/home/nirosh/frappe-bench/apps/frappe/frappe/utils/redis_wrapper.py", line 81, in get_value
    val = generator()
  File "/home/nirosh/frappe-bench/apps/frappe/frappe/utils/caching.py", line 57, in wrapper
    return_val = func(*args, **kwargs)
  File "/home/nirosh/frappe-bench/apps/frappe/frappe/__init__.py", line 1476, in _load_app_hooks
    apps = [app_name] if app_name else get_installed_apps(_ensure_on_bench=True)
  File "/home/nirosh/frappe-bench/apps/frappe/frappe/utils/caching.py", line 57, in wrapper
    return_val = func(*args, **kwargs)
  File "/home/nirosh/frappe-bench/apps/frappe/frappe/__init__.py", line 1432, in get_installed_apps
    installed = json.loads(db.get_global("installed_apps") or "[]")
  File "/home/nirosh/frappe-bench/apps/frappe/frappe/database/database.py", line 975, in get_global
    return self.get_default(key, user)
  File "/home/nirosh/frappe-bench/apps/frappe/frappe/database/database.py", line 979, in get_default
    d = self.get_defaults(key, parent)
  File "/home/nirosh/frappe-bench/apps/frappe/frappe/database/database.py", line 995, in get_defaults
    defaults = frappe.defaults.get_defaults_for(parent)
  File "/home/nirosh/frappe-bench/apps/frappe/frappe/defaults.py", line 238, in get_defaults_for
    frappe.qb.from_(table)
  File "/home/nirosh/frappe-bench/apps/frappe/frappe/query_builder/utils.py", line 87, in execute_query
    result = frappe.db.sql(query, params, *args, **kwargs)  # nosemgrep
  File "/home/nirosh/frappe-bench/apps/frappe/frappe/database/database.py", line 201, in sql
    self.connect()
  File "/home/nirosh/frappe-bench/apps/frappe/frappe/database/database.py", line 115, in connect
    self._conn = self.get_connection()
  File "/home/nirosh/frappe-bench/apps/frappe/frappe/database/mariadb/database.py", line 98, in get_connection
    conn = self._get_connection()
  File "/home/nirosh/frappe-bench/apps/frappe/frappe/database/mariadb/database.py", line 104, in _get_connection
    return self.create_connection()
  File "/home/nirosh/frappe-bench/apps/frappe/frappe/database/mariadb/database.py", line 107, in create_connection
    return pymysql.connect(**self.get_connection_settings())
  File "/home/nirosh/frappe-bench/env/lib/python3.10/site-packages/pymysql/connections.py", line 352, in __init__
    self.connect()
  File "/home/nirosh/frappe-bench/env/lib/python3.10/site-packages/pymysql/connections.py", line 636, in connect
    self._request_authentication()
  File "/home/nirosh/frappe-bench/env/lib/python3.10/site-packages/pymysql/connections.py", line 911, in _request_authentication
    auth_packet = self._read_packet()
  File "/home/nirosh/frappe-bench/env/lib/python3.10/site-packages/pymysql/connections.py", line 729, in _read_packet
    packet.raise_for_error()
  File "/home/nirosh/frappe-bench/env/lib/python3.10/site-packages/pymysql/protocol.py", line 221, in raise_for_error
    err.raise_mysql_exception(self._data)
  File "/home/nirosh/frappe-bench/env/lib/python3.10/site-packages/pymysql/err.py", line 143, in raise_mysql_exception
    raise errorclass(errno, errval)
pymysql.err.OperationalError: (1698, "Access denied for user '_e62c1393ab75f65c'@'localhost'")
